Workbook

Sheet Diagrama ER (corregido)

Sheet Tipos de Dato
A1: Tipos de Datos - Tabla Comparativa
A2: # | B2: Tipo de Dato Genérico | C2: Descripción | D2: En PosgreSQL | E2: En MySQL | F2: En MS SQL Server
D3: Versión: 18 | E3: Versión: 8.4 | F3: Versión: 2025
A4: 1 | B4: AUTOINCREMENTABLE | C4: Clave numérica que se autoincrementa. | D4: SERIAL / BIGSERIAL (o columna IDENTITY) | E4: AUTO_INCREMENT | F4: IDENTITY(1,1)
A5: =A4+1 -> 2 | B5: UUID | C5: Identificador único universal (GUID). | D5: UUID | E5: CHAR(36) o BINARY(16) | F5: UNIQUEIDENTIFIER
A6: =A5+1 -> 3 | B6: ENTERO | C6: Números enteros con/sin signo. | D6: INTEGER / INT / SMALLINT / BIGINT | E6: INT / TINYINT / SMALLINT / MEDIUMINT / BIGINT | F6: INT / BIGINT / SMALLINT / TINYINT
A7: =A6+1 -> 4 | B7: DECIMAL | C7: Números con precisión fija (coma flotante). | D7: DECIMAL / NUMERIC | E7: DECIMAL / NUMERIC | F7: DECIMAL / NUMERIC
A8: =A7+1 -> 5 | B8: LÓGICO | C8: Valores booleanos (Verdadero/Falso). | D8: BOOLEAN | E8: BOOLEAN / BOOL (alias de TINYINT(1)) | F8: BIT
A9: =A8+1 -> 6 | B9: TEXTO | C9: Grandes bloques de texto de longitud variable. | D9: TEXT | E9: TEXT / TINYTEXT / MEDIUMTEXT / LONGTEXT | F9: VARCHAR(MAX) (recomendado) o TEXT (obsoleto)
A10: =A9+1 -> 7 | B10: CARACTER | C10: Cadenas de caracteres de longitud fija. | D10: CHAR(n) | E10: CHAR(n) | F10: CHAR(n) / NCHAR(n)
A11: =A10+1 -> 8 | B11: FECHA | C11: Fecha (año, mes, día). | D11: DATE | E11: DATE | F11: DATE
A12: =A11+1 -> 9 | B12: FECHA_HORA | C12: Fecha y hora (timestamp). | D12: TIMESTAMP | E12: DATETIME / TIMESTAMP | F12: DATETIME2 / DATETIME / SMALLDATETIME
A13: =A12+1 -> 10 | B13: HORA | C13: Hora del día (hora, minuto, segundo). | D13: TIME | E13: TIME | F13: TIME
A14: =A13+1 -> 11 | B14: URL | C14: Almacenamiento de direcciones web (URL). | D14: VARCHAR(n) o TEXT | E14: VARCHAR(n) o TEXT | F14: VARCHAR(n) o NVARCHAR(n)
A15: =A14+1 -> 12 | B15: ENUM | C15: Lista predefinida de valores permitidos. | D15: CREATE TYPE ... AS ENUM | E15: ENUM('val1','val2',...) | F15: VARCHAR + CHECK (no tiene tipo ENUM nativo)
A16: =A15+1 -> 13 | B16: TEXTO_CORTO | C16: Cadenas de caracteres de longitud variable. | D16: VARCHAR(n) | E16: VARCHAR(n) | F16: VARCHAR(n) / NVARCHAR(n)
... A21: =A20+1 -> 18 | B21: AUDIO | C21: Archivos de audio (MP3, WAV, etc.). | D21: BYTEA | E21: BLOB / LONGBLOB | F21: VARBINARY(MAX)

Sheet Invetario de Tablas
A1: Modelo Lógico - Tablas resultantes del Diccionario Genérico (corregido)
A2: INVENTARIO DE TABLAS Este inventario es el mismo para los 3 SGBDs: PostgreSQL, MySQL y MS SQL Server. Todos los diccionarios deben tomar la misma cantidad y los mismos nombres de esta tablas
A3: # | B3: Tabla | C3: Descripción Tabla | D3: Observaciones
A4: 1 | B4: rol | C4: Define los tipos de usuario del sistema | D4: Control de acceso
A5: =A4+1 -> 2 | B5: usuario | C5: Usuarios del sistema | D5: FK hacia roles
A6: =A5+1 -> 3 | B6: apiario | C6: Ubicación de colmenas | D6: Unidad productiva
A7: =A6+1 -> 4 | B7: colmena | C7: Colmenas del apiario | D7: FK hacia apiarios
A8: =A7+1 -> 5 | B8: sensor_iot | C8: Sensores instalados | D8: FK hacia colmenas
A9: =A8+1 -> 6 | B9: dato_sensor | C9: Datos capturados | D9: Datos históricos
A10: =A9+1 -> 7 | B10: producto | C10: Productos apícolas | D10: Usado en ventas
A11: =A10+1 -> 8 | B11: pedido | C11: Registro de pedidos | D11: Transacciones
A12: =A11+1 -> 9 | B12: detalle_pedido | C12: Detalle de productos por pedido | D12: Tabla intermedia
A13: =A12+1 -> 10 | B13: certificacion | C13: Certificaciones apícolas | D13: Regulación
A14: =A13+1 -> 11 | B14: inspeccion | C14: Inspecciones realizadas | D14: Control sanitario
A15: =A14+1 -> 12 | B15: entidades_regulatoria | C15: Entidades de control | D15: Supervisión
A16: =A15+1 -> 13 | B16: lotes_produccion | C16: Lotes de producción | D16: Producción
... A19: =A18+1 -> 16 | B19: producto_lote | C19: Relación productos-lotes | D19: Tabla M:N
A20: =A19+1 -> 17
A21: =A20+1 -> 18
A22: =A21+1 -> 19
A23: =A22+1 -> 20
A24: =A23+1 -> 21
A25: =A24+1 -> 22
A26: =A25+1 -> 23
A27: =A26+1 -> 24
A28: =A27+1 -> 25

Sheet Diccionario Datos - PostgreSQL
A1: PostgreSQL - Tablas en Detalle
A3: ='Invetario de Tablas'!A4 -> 1 | B3: Tabla | C3: ='Invetario de Tablas'!B4 -> rol | G3: Descripción Tabla | K3: ='Invetario de Tablas'!C4 -> Define los tipos de usuario del sistema | X3: Versión | Y3: 18
A4: # | B4: Campo | C4: Descripción Campo | G4: Tipo Dato - PostgreSQL | K4: Tamaño | O4: Nulo | R4: PK | T4: FK | V4: UK | X4: Nota/Comentarios
A5: 1 | B5: id_rol | C5: identificacion del rol | G5: SERIAL | O5: no | R5: s | V5: s | X5: clave primaria
A6: 2 | B6: nombre | C6: nombre del rol | G6: VARCHAR | K6: 50 | O6: no | V6: s | X6: valor unico
A8: ='Invetario de Tablas'!A5 -> 2 | B8: Tabla | C8: ='Invetario de Tablas'!B5 -> usuario | G8: Descripción Tabla | K8: ='Invetario de Tablas'!C5 -> Usuarios del sistema | X8: Versión | Y8: 18
A9: # | B9: Campo | C9: Descripción Campo | G9: Tipo Dato - PostgreSQL | K9: Tamaño | O9: Nulo | R9: PK | T9: FK | V9: UK | X9: Nota/Comentarios
A10: 1 | B10: id_usuarios | C10: identificacion de usuario | G10: SERIAL | O10: no | R10: s | V10: s | X10: clave primaria
A11: 2 | B11: nombre | C11: nombre del usuario | G11: VARCHAR | K11: 100 | O11: no
A12: 3 | B12: correo | C12: correo electronico | G12: VARCHAR | K12: 100 | O12: no | V12: s | X12: unico
A13: 4 | B13: id_rol | C13: rol asignado | G13: INT | O13: no | T13: s | X13: relacion con roles
A15: 3 | B15: Tabla | C15: apiario | G15: Descripción Tabla | K15: Ubicación de colmenas | X15: Versión | Y15: 18
A16: # | B16: Campo | C16: Descripción Campo | G16: Tipo Dato - PostgreSQL | K16: Tamaño | O16: Nulo | R16: PK | T16: FK | V16: UK | X16: Nota/Comentarios
A17: 1 | B17: id_apiarios | C17: identificador | G17: SERIAL | O17: no | R17: s | V17: s | X17: clave primaria
A18: 2 | B18: ubicación | C18: ubicación de apiario | G18: VARCHAR | K18: 150 | O18: no
A20: 4 | B20: Tabla | C20: colmena | G20: Descripción Tabla | K20: Registra colmenas | X20: Versión | Y20: 18
A21: # | B21: Campo | C21: Descripción Campo | G21: Tipo Dato - PostgreSQL | K21: Tamaño | O21: Nulo | R21: PK | T21: FK | V21: UK | X21: Nota/Comentarios
A22: 1 | B22: id_colmenas | C22: identificacion de usuario | G22: SERIAL | O22: no | R22: s | V22: s | X22: clave primaria
A23: 2 | B23: id_apiarios | C23: nombre del usuario | G23: INT | O23: no | T23: s | X23: Relacion con apiarios
A24: 3 | B24: estado | C24: correo electronico | G24: VARCHAR | K24: 50 | O24: si
A27: 5 | B27: Tabla | C27: sensor_iot | G27: Descripción Tabla | K27: sensores instalados | X27: Versión | Y27: 18
A28: # | B28: Campo | C28: Descripción Campo | G28: Tipo Dato - PostgreSQL | K28: Tamaño | O28: Nulo | R28: PK | T28: FK | V28: UK | X28: Nota/Comentarios
A29: 1 | B29: id_sensor | C29: identificador | G29: SERIAL | O29: no | R29: s | V29: s | X29: clave primaria
A30: 2 | B30: id_colmena | C30: colmena asociada | G30: INT | O30: no | T30: s | X30: relacion con colmenas
A31: 3 | B31: tipo | C31: tipo de sensor | G31: VARCHAR | K31: 50 | O31: no
A35: 6 | B35: Tabla | C35: dato_sensor | G35: Descripción Tabla | K35: Registros de sensores | X35: Versión | Y35: 18
A36: # | B36: Campo | C36: Descripción Campo | G36: Tipo Dato - PostgreSQL | K36: Tamaño | O36: Nulo | R36: PK | T36: FK | V36: UK | X36: Nota/Comentarios
A37: 1 | B37: id_dato | C37: identificador del dato | G37: SERIAL | O37: no | R37: s | V37: s | X37: clave primaria
A38: 2 | B38: id_sensor | C38: sensor asociado | G38: INT | O38: no | T38: S | X38: Relacion con sensores
A39: 3 | B39: valor | C39: valor medido | G39: Decimal | K39: 10.2 | O39: no
A40: 4 | B40: fecha | C40: fecha del registro | G40: TIMESTAMP | O40: no
A42: 7 | B42: Tabla | C42: producto | G42: Descripción Tabla | K42: Productos apícolas | X42: Versión | Y42: 18
A43: # | B43: Campo | C43: Descripción Campo | G43: Tipo Dato - PostgreSQL | K43: Tamaño | O43: Nulo | R43: PK | T43: FK | V43: UK | X43: Nota/Comentarios
A44: 1 | B44: id_producto | C44: Identificador del producto | G44: SERIAL | O44: no | R44: s | V44: s | X44: clave primaria
A45: 2 | B45: nombre | C45: nombre del producto | G45: VARCHAR | K45: 100 | O45: no
A46: 3 | B46: precio | C46: precio | G46: DECIMAL | K46: 10.2 | O46: no
A48: 8 | B48: Tabla | C48: pedido | G48: Descripción Tabla | K48: Ordenes de compra | X48: Versión | Y48: 18
A49: # | B49: Campo | C49: Descripción Campo | G49: Tipo Dato - PostgreSQL | K49: Tamaño | O49: Nulo | R49: PK | T49: FK | V49: UK | X49: Nota/Comentarios
A50: 1 | B50: id_pedido | C50: identificador del pedido | G50: SERIAL | O50: no | R50: s | V50: s | X50: clave primaria
A51: 2 | B51: fecha | C51: fecha del pedido | G51: DATE | O51: no
...

Sheet Diccionario Datos - MySQL
A1: MySQL - Tablas en Detalle
A3: ='Invetario de Tablas'!A4 -> 1 | B3: Tabla | C3: ='Invetario de Tablas'!B4 -> rol | G3: Descripción Tabla | K3: ='Invetario de Tablas'!C4 -> Define los tipos de usuario del sistema | X3: Versión | Y3: 8
A4: # | B4: Campo | C4: Descripción Campo | G4: Tipo Dato - MySQL | K4: Tamaño | O4: Nulo | R4: PK | T4: FK | V4: UK | X4: Nota/Comentarios
A5: 1 | B5: ='Diccionario Datos - PostgreSQL'!B5 -> id_rol | C5: ='Diccionario Datos - PostgreSQL'!C5 -> identificacion del rol | G5: AUTO_INCREMENT | O5: no | R5: ='Diccionario Datos - PostgreSQL'!R5 -> s | V5: s | X5: ='Diccionario Datos - PostgreSQL'!X5 -> clave primaria
A6: 2 | B6: ='Diccionario Datos - PostgreSQL'!B6 -> nombre | C6: ='Diccionario Datos - PostgreSQL'!C6 -> nombre del rol | G6: VARCHAR | K6: ='Diccionario Datos - PostgreSQL'!K6 -> 50 | O6: no | V6: s | X6: ='Diccionario Datos - PostgreSQL'!X6 -> valor unico
A8: ='Invetario de Tablas'!A5 -> 2 | B8: Tabla | C8: ='Invetario de Tablas'!B5 -> usuario | G8: Descripción Tabla | K8: ='Invetario de Tablas'!C5 -> Usuarios del sistema | X8: Versión | Y8: 8
A9: # | B9: Campo | C9: Descripción Campo | G9: Tipo Dato - MySQL | K9: Tamaño | O9: Nulo | R9: PK | T9: FK | V9: UK | X9: Nota/Comentarios
A10: 1 | B10: ='Diccionario Datos - PostgreSQL'!B10 -> id_usuarios | C10: ='Diccionario Datos - PostgreSQL'!C10 -> identificacion de usuario | G10: AUTO_INCREMENT | K10: ='Diccionario Datos - PostgreSQL'!K10 | O10: ='Diccionario Datos - PostgreSQL'!O10 -> no | R10: S | V10: S | X10: ='Diccionario Datos - PostgreSQL'!X10 -> clave primaria
A11: 2 | B11: ='Diccionario Datos - PostgreSQL'!B11 -> nombre | C11: ='Diccionario Datos - PostgreSQL'!C11 -> nombre del usuario | G11: VARCHAR | K11: ='Diccionario Datos - PostgreSQL'!K11 -> 100 | O11: ='Diccionario Datos - PostgreSQL'!O11 -> no | X11: ='Diccionario Datos - PostgreSQL'!X11
A12: 3 | B12: ='Diccionario Datos - PostgreSQL'!B12 -> correo | C12: ='Diccionario Datos - PostgreSQL'!C12 -> correo electronico | G12: VARCHAR | K12: ='Diccionario Datos - PostgreSQL'!K12 -> 100 | O12: ='Diccionario Datos - PostgreSQL'!O12 -> no | V12: S | X12: ='Diccionario Datos - PostgreSQL'!X12 -> unico
A13: 4 | B13: ='Diccionario Datos - PostgreSQL'!B13 -> id_rol | C13: ='Diccionario Datos - PostgreSQL'!C13 -> rol asignado | G13: INT | K13: ='Diccionario Datos - PostgreSQL'!K13 | O13: ='Diccionario Datos - PostgreSQL'!O13 -> no | T13: S | X13: ='Diccionario Datos - PostgreSQL'!X13 -> relacion con roles
A15: ='Diccionario Datos - PostgreSQL'!A15 -> 3 | B15: Tabla | C15: ='Diccionario Datos - PostgreSQL'!C15 -> apiario | G15: Descripción Tabla | K15: ='Diccionario Datos - PostgreSQL'!K15 -> Ubicación de colmenas | X15: Versión | Y15: 8
A16: # | B16: Campo | C16: Descripción Campo | G16: Tipo Dato - MySQL | K16: Tamaño | O16: Nulo | R16: PK | T16: FK | V16: UK | X16: Nota/Comentarios
A17: 1 | B17: ='Diccionario Datos - PostgreSQL'!B17 -> id_apiarios | C17: ='Diccionario Datos - PostgreSQL'!C17 -> identificador | G17: AUTO_INCREMENT | K17: ='Diccionario Datos - PostgreSQL'!K17 | O17: ='Diccionario Datos - PostgreSQL'!O17 -> no | R17: S | V17: S | X17: ='Diccionario Datos - PostgreSQL'!X17 -> clave primaria
A18: 2 | B18: ='Diccionario Datos - PostgreSQL'!B18 -> ubicación | C18: ='Diccionario Datos - PostgreSQL'!C18 -> ubicación de apiario | G18: VARCHAR | K18: ='Diccionario Datos - PostgreSQL'!K18 -> 150 | O18: ='Diccionario Datos - PostgreSQL'!O18 -> no | X18: ='Diccionario Datos - PostgreSQL'!X18
A20: ='Diccionario Datos - PostgreSQL'!A20 -> 4 | B20: Tabla | C20: ='Diccionario Datos - PostgreSQL'!C20 -> colmena | G20: Descripción Tabla | K20: ='Diccionario Datos - PostgreSQL'!K20 -> Registra colmenas | X20: Versión | Y20: 8
A21: # | B21: Campo | C21: Descripción Campo | G21: Tipo Dato - MySQL | K21: Tamaño | O21: Nulo | R21: PK | T21: FK | V21: UK | X21: Nota/Comentarios
A22: 1 | B22: ='Diccionario Datos - PostgreSQL'!B22 -> id_colmenas | C22: ='Diccionario Datos - PostgreSQL'!C22 -> identificacion de usuario | G22: AUTO_INCREMENT | K22: ='Diccionario Datos - PostgreSQL'!K22 | O22: ='Diccionario Datos - PostgreSQL'!O22 -> no | R22: S | V22: S | X22: ='Diccionario Datos - PostgreSQL'!X22 -> clave primaria
A23: 2 | B23: ='Diccionario Datos - PostgreSQL'!B23 -> id_apiarios | C23: ='Diccionario Datos - PostgreSQL'!C23 -> nombre del usuario | G23: INT | O23: ='Diccionario Datos - PostgreSQL'!O23 -> no | T23: S | X23: ='Diccionario Datos - PostgreSQL'!X23 -> Relacion con apiarios
A24: 3 | B24: ='Diccionario Datos - PostgreSQL'!B24 -> estado | C24: ='Diccionario Datos - PostgreSQL'!C24 -> correo electronico | G24: VARCHAR | K24: 50 | O24: ='Diccionario Datos - PostgreSQL'!O24 -> si | X24: ='Diccionario Datos - PostgreSQL'!X24
A26: ='Diccionario Datos - PostgreSQL'!A27 -> 5 | B26: Tabla | C26: ='Diccionario Datos - PostgreSQL'!C27 -> sensor_iot | G26: Descripción Tabla | K26: ='Diccionario Datos - PostgreSQL'!K27 -> sensores instalados | X26: Versión | Y26: 8
A27: # | B27: Campo | C27: Descripción Campo | G27: Tipo Dato - MySQL | K27: Tamaño | O27: Nulo | R27: PK | T27: FK | V27: UK | X27: Nota/Comentarios
A28: 1 | B28: ='Diccionario Datos - PostgreSQL'!B29 -> id_sensor | C28: ='Diccionario Datos - PostgreSQL'!C29 -> identificador | G28: AUTO_INCREMENT | O28: no | R28: s | V28: S | X28: ='Diccionario Datos - PostgreSQL'!X29 -> clave primaria
A29: 2 | B29: ='Diccionario Datos - PostgreSQL'!B30 -> id_colmena | C29: ='Diccionario Datos - PostgreSQL'!C30 -> colmena asociada | G29: INT | O29: ='Diccionario Datos - PostgreSQL'!O29 -> no | T29: S | X29: ='Diccionario Datos - PostgreSQL'!X30 -> relacion con colmenas
A30: 3 | B30: ='Diccionario Datos - PostgreSQL'!B31 -> tipo | C30: ='Diccionario Datos - PostgreSQL'!C31 -> tipo de sensor | G30: VARCHAR | K30: 50 | O30: ='Diccionario Datos - PostgreSQL'!O30 -> no | X30: ='Diccionario Datos - PostgreSQL'!X31
A32: ='Diccionario Datos - PostgreSQL'!A35 -> 6 | B32: Tabla | C32: ='Diccionario Datos - PostgreSQL'!C35 -> dato_sensor | G32: Descripción Tabla | K32: ='Diccionario Datos - PostgreSQL'!K35 -> Registros de sensores | X32: Versión | Y32: 8
A33: # | B33: Campo | C33: Descripción Campo | G33: Tipo Dato - MySQL | K33: Tamaño | O33: Nulo | R33: PK | T33: FK | V33: UK | X33: Nota/Comentarios
A34: 1 | B34: ='Diccionario Datos - PostgreSQL'!B37 -> id_dato | C34: ='Diccionario Datos - PostgreSQL'!C37 -> identificador del dato | G34: AUTO_INCREMENT | K34: ='Diccionario Datos - PostgreSQL'!K37 | O34: ='Diccionario Datos - PostgreSQL'!O37 -> no | R34: s | V34: S | X34: ='Diccionario Datos - PostgreSQL'!X37 -> clave primaria
A35: 2 | B35: ='Diccionario Datos - PostgreSQL'!B38 -> id_sensor | C35: ='Diccionario Datos - PostgreSQL'!C38 -> sensor asociado | G35: INT | K35: ='Diccionario Datos - PostgreSQL'!K38 | O35: ='Diccionario Datos - PostgreSQL'!O38 -> no | T35: S | X35: ='Diccionario Datos - PostgreSQL'!X38 -> Relacion con sensores
A36: 3 | B36: ='Diccionario Datos - PostgreSQL'!B39 -> valor | C36: ='Diccionario Datos - PostgreSQL'!C39 -> valor medido | G36: DECIMAL | K36: ='Diccionario Datos - PostgreSQL'!K39 -> 10.2 | O36: ='Diccionario Datos - PostgreSQL'!O39 -> no | X36: ='Diccionario Datos - PostgreSQL'!X39
A37: 4 | B37: ='Diccionario Datos - PostgreSQL'!B40 -> fecha | C37: ='Diccionario Datos - PostgreSQL'!C40 -> fecha del registro | G37: TIMESTAMP | K37: ='Diccionario Datos - PostgreSQL'!K40 | O37: ='Diccionario Datos - PostgreSQL'!O40 -> no | X37: ='Diccionario Datos - PostgreSQL'!X40
A39: ='Diccionario Datos - PostgreSQL'!A42 -> 7 | B39: Tabla | C39: ='Diccionario Datos - PostgreSQL'!C40 -> fecha del registro | G39: Descripción Tabla | K39: ='Diccionario Datos - PostgreSQL'!K42 -> Productos apícolas | X39: Versión | Y39: 8
A40: # | B40: Campo | C40: Descripción Campo | G40: Tipo Dato - MySQL | K40: Tamaño | O40: Nulo | R40: PK | T40: FK | V40: UK | X40: Nota/Comentarios
A41: 1 | B41: ='Diccionario Datos - PostgreSQL'!B44 -> id_producto | C41: ='Diccionario Datos - PostgreSQL'!C44 -> Identificador del producto | G41: AUTO_INCREMENT | K41: ='Diccionario Datos - PostgreSQL'!K44 | O41: ='Diccionario Datos - PostgreSQL'!O44 -> no | R41: s | V41: S | X41: ='Diccionario Datos - PostgreSQL'!X44 -> clave primaria
A42: 2 | B42: ='Diccionario Datos - PostgreSQL'!B45 -> nombre | C42: ='Diccionario Datos - PostgreSQL'!C45 -> nombre del producto | G42: VARCHAR | K42: ='Diccionario Datos - PostgreSQL'!K45 -> 100 | O42: ='Diccionario Datos - PostgreSQL'!O45 -> no | X42: ='Diccionario Datos - PostgreSQL'!X45
A43: 3 | B43: ='Diccionario Datos - PostgreSQL'!B46 -> precio | C43: ='Diccionario Datos - PostgreSQL'!C46 -> precio | G43: DECIMAL | K43: ='Diccionario Datos - PostgreSQL'!K46 -> 10.2 | O43: ='Diccionario Datos - PostgreSQL'!O46 -> no | X43: ='Diccionario Datos - PostgreSQL'!X46
A45: ='Diccionario Datos - PostgreSQL'!A48 -> 8 | B45: Tabla | C45: ='Diccionario Datos - PostgreSQL'!C48 -> pedido | G45: Descripción Tabla | K45: ='Diccionario Datos - PostgreSQL'!K48 -> Ordenes de compra | X45: Versión | Y45: 8
A46: # | B46: Campo | C46: Descripción Campo | G46: Tipo Dato - MySQL | K46: Tamaño | O46: Nulo | R46: PK | T46: FK | V46: UK | X46: Nota/Comentarios
A47: 1 | B47: ='Diccionario Datos - PostgreSQL'!B50 -> id_pedido | C47: ='Diccionario Datos - PostgreSQL'!C50 -> identificador del pedido | G47: AUTO_INCREMENT | K47: ='Diccionario Datos - PostgreSQL'!K50 | O47: ='Diccionario Datos - PostgreSQL'!O50 -> no | R47: s | V47: S | X47: ='Diccionario Datos - PostgreSQL'!X50 -> clave primaria
A48: 2 | B48: ='Diccionario Datos - PostgreSQL'!B51 -> fecha | C48: ='Diccionario Datos - PostgreSQL'!C51 -> fecha del pedido | G48: DATE | K48: ='Diccionario Datos - PostgreSQL'!K51 | O48: ='Diccionario Datos - PostgreSQL'!O51 -> no | X48: ='Diccionario Datos - PostgreSQL'!X51
...

Sheet Diccionario Datos - MS SQL Serv
A1: MS SQL Server - Tablas en Detalle
A3: ='Invetario de Tablas'!A4 -> 1 | B3: Tabla | C3: ='Invetario de Tablas'!B4 -> rol | G3: Descripción Tabla | K3: ='Invetario de Tablas'!C4 -> Define los tipos de usuario del sistema | X3: Versión | Y3: 2025
A4: # | B4: Campo | C4: Descripción Campo | G4: Tipo Dato - MS SQL Server | K4: Tamaño | O4: Nulo | R4: PK | T4: FK | V4: UK | X4: Nota/Comentarios
A5: 1 | B5: ='Diccionario Datos - PostgreSQL'!B5 -> id_rol | C5: ='Diccionario Datos - PostgreSQL'!C5 -> identificacion del rol | G5: IDENTITY | K5: ='Diccionario Datos - PostgreSQL'!K5 | O5: ='Diccionario Datos - PostgreSQL'!O5 -> no | R5: ='Diccionario Datos - PostgreSQL'!R5 -> s | T5: ='Diccionario Datos - PostgreSQL'!T5 | V5: ='Diccionario Datos - PostgreSQL'!V5 -> s | X5: ='Diccionario Datos - PostgreSQL'!X5 -> clave primaria
A6: 2 | B6: ='Diccionario Datos - PostgreSQL'!B6 -> nombre | C6: ='Diccionario Datos - PostgreSQL'!C6 -> nombre del rol | G6: VARCHAR | K6: ='Diccionario Datos - PostgreSQL'!K6 -> 50 | O6: ='Diccionario Datos - PostgreSQL'!O6 -> no | R6: ='Diccionario Datos - PostgreSQL'!R6 | T6: ='Diccionario Datos - PostgreSQL'!T6 | V6: ='Diccionario Datos - PostgreSQL'!V6 -> s | X6: ='Diccionario Datos - PostgreSQL'!X6 -> valor unico
A8: ='Invetario de Tablas'!A5 -> 2 | B8: Tabla | C8: ='Invetario de Tablas'!B5 -> usuario | G8: Descripción Tabla | K8: ='Invetario de Tablas'!C5 -> Usuarios del sistema | X8: Versión | Y8: 2025
A9: # | B9: Campo | C9: Descripción Campo | G9: Tipo Dato - MS SQL Server | K9: Tamaño | O9: Nulo | R9: PK | T9: FK | V9: UK | X9: Nota/Comentarios
A10: 1 | B10: ='Diccionario Datos - PostgreSQL'!B10 -> id_usuarios | C10: ='Diccionario Datos - PostgreSQL'!C10 -> identificacion de usuario | G10: IDENTITY | K10: ='Diccionario Datos - PostgreSQL'!K10 | O10: ='Diccionario Datos - PostgreSQL'!O10 -> no | R10: S | V10: S | X10: ='Diccionario Datos - PostgreSQL'!X10 -> clave primaria
A11: 2 | B11: ='Diccionario Datos - PostgreSQL'!B11 -> nombre | C11: ='Diccionario Datos - PostgreSQL'!C11 -> nombre del usuario | G11: VARCHAR | K11: ='Diccionario Datos - PostgreSQL'!K11 -> 100 | O11: ='Diccionario Datos - PostgreSQL'!O11 -> no | X11: ='Diccionario Datos - PostgreSQL'!X11
A12: 3 | B12: ='Diccionario Datos - PostgreSQL'!B12 -> correo | C12: ='Diccionario Datos - PostgreSQL'!C12 -> correo electronico | G12: VARCHAR | K12: ='Diccionario Datos - PostgreSQL'!K12 -> 100 | O12: ='Diccionario Datos - PostgreSQL'!O12 -> no | V12: S | X12: ='Diccionario Datos - PostgreSQL'!X12 -> unico
A13: 4 | B13: ='Diccionario Datos - PostgreSQL'!B13 -> id_rol | C13: ='Diccionario Datos - PostgreSQL'!C13 -> rol asignado | G13: INT | K13: ='Diccionario Datos - PostgreSQL'!K13 | O13: ='Diccionario Datos - PostgreSQL'!O13 -> no | T13: S | X13: ='Diccionario Datos - PostgreSQL'!X13 -> relacion con roles
A15: ='Diccionario Datos - PostgreSQL'!A15 -> 3 | B15: Tabla | C15: ='Diccionario Datos - PostgreSQL'!C15 -> apiario | G15: Descripción Tabla | K15: ='Diccionario Datos - PostgreSQL'!K15 -> Ubicación de colmenas | X15: Versión | Y15: 2025
A16: # | B16: Campo | C16: Descripción Campo | G16: Tipo Dato - MS SQL Server | K16: Tamaño | O16: Nulo | R16: PK | T16: FK | V16: UK | X16: Nota/Comentarios
A17: 1 | B17: ='Diccionario Datos - PostgreSQL'!B17 -> id_apiarios | C17: ='Diccionario Datos - PostgreSQL'!C17 -> identificador | G17: IDENTITY | K17: ='Diccionario Datos - PostgreSQL'!K17 | O17: ='Diccionario Datos - PostgreSQL'!O17 -> no | R17: S | V17: S | X17: ='Diccionario Datos - PostgreSQL'!X17 -> clave primaria
A18: 2 | B18: ='Diccionario Datos - PostgreSQL'!B18 -> ubicación | C18: ='Diccionario Datos - PostgreSQL'!C18 -> ubicación de apiario | G18: VARCHAR | K18: ='Diccionario Datos - PostgreSQL'!K18 -> 150 | O18: ='Diccionario Datos - PostgreSQL'!O18 -> no | X18: ='Diccionario Datos - PostgreSQL'!X18
A20: ='Diccionario Datos - PostgreSQL'!A20 -> 4 | B20: Tabla | C20: ='Diccionario Datos - PostgreSQL'!C20 -> colmena | G20: Descripción Tabla | K20: ='Diccionario Datos - PostgreSQL'!K20 -> Registra colmenas | X20: Versión | Y20: 2025
A21: # | B21: Campo | C21: Descripción Campo | G21: Tipo Dato - MS SQL Server | K21: Tamaño | O21: Nulo | R21: PK | T21: FK | V21: UK | X21: Nota/Comentarios
A22: 1 | B22: ='Diccionario Datos - PostgreSQL'!B22 -> id_colmenas | C22: ='Diccionario Datos - PostgreSQL'!C22 -> identificacion de usuario | G22: IDENTITY | K22: ='Diccionario Datos - PostgreSQL'!K22 | O22: ='Diccionario Datos - PostgreSQL'!O22 -> no | R22: S | V22: S | X22: ='Diccionario Datos - PostgreSQL'!X22 -> clave primaria
A23: 2 | B23: ='Diccionario Datos - PostgreSQL'!B23 -> id_apiarios | C23: ='Diccionario Datos - PostgreSQL'!C23 -> nombre del usuario | G23: INT | O23: ='Diccionario Datos - PostgreSQL'!O23 -> no | T23: S | X23: ='Diccionario Datos - PostgreSQL'!X23 -> Relacion con apiarios
A24: 3 | B24: ='Diccionario Datos - PostgreSQL'!B24 -> estado | C24: ='Diccionario Datos - PostgreSQL'!C24 -> correo electronico | G24: VARCHAR | K24: 50 | O24: ='Diccionario Datos - PostgreSQL'!O24 -> si | X24: ='Diccionario Datos - PostgreSQL'!X24
A26: ='Diccionario Datos - PostgreSQL'!A27 -> 5 | B26: Tabla | C26: ='Diccionario Datos - PostgreSQL'!C27 -> sensor_iot | G26: Descripción Tabla | K26: ='Diccionario Datos - PostgreSQL'!K27 -> sensores instalados | X26: Versión | Y26: 2025
A27: # | B27: Campo | C27: Descripción Campo | G27: Tipo Dato - MS SQL Server | K27: Tamaño | O27: Nulo | R27: PK | T27: FK | V27: UK | X27: Nota/Comentarios
A28: 1 | B28: ='Diccionario Datos - PostgreSQL'!B29 -> id_sensor | C28: ='Diccionario Datos - PostgreSQL'!C29 -> identificador | G28: IDENTITY | O28: no | R28: s | V28: S | X28: ='Diccionario Datos - PostgreSQL'!X29 -> clave primaria
A29: 2 | B29: ='Diccionario Datos - PostgreSQL'!B30 -> id_colmena | C29: ='Diccionario Datos - PostgreSQL'!C30 -> colmena asociada | G29: INT | O29: ='Diccionario Datos - PostgreSQL'!O29 -> no | T29: S | X29: ='Diccionario Datos - PostgreSQL'!X30 -> relacion con colmenas
A30: 3 | B30: ='Diccionario Datos - PostgreSQL'!B31 -> tipo | C30: ='Diccionario Datos - PostgreSQL'!C31 -> tipo de sensor | G30: VARCHAR | K30: 50 | O30: ='Diccionario Datos - PostgreSQL'!O30 -> no | X30: ='Diccionario Datos - PostgreSQL'!X31
A32: ='Diccionario Datos - PostgreSQL'!A35 -> 6 | B32: Tabla | C32: ='Diccionario Datos - PostgreSQL'!C35 -> dato_sensor | G32: Descripción Tabla | K32: ='Diccionario Datos - PostgreSQL'!K35 -> Registros de sensores | X32: Versión | Y32: 2025
A33: # | B33: Campo | C33: Descripción Campo | G33: Tipo Dato - MS SQL Server | K33: Tamaño | O33: Nulo | R33: PK | T33: FK | V33: UK | X33: Nota/Comentarios
A34: 1 | B34: ='Diccionario Datos - PostgreSQL'!B37 -> id_dato | C34: ='Diccionario Datos - PostgreSQL'!C37 -> identificador del dato | G34: IDENTITY | K34: ='Diccionario Datos - PostgreSQL'!K37 | O34: ='Diccionario Datos - PostgreSQL'!O37 -> no | R34: s | V34: S | X34: ='Diccionario Datos - PostgreSQL'!X37 -> clave primaria
A35: 2 | B35: ='Diccionario Datos - PostgreSQL'!B38 -> id_sensor | C35: ='Diccionario Datos - PostgreSQL'!C38 -> sensor asociado | G35: INT | K35: ='Diccionario Datos - PostgreSQL'!K38 | O35: ='Diccionario Datos - PostgreSQL'!O38 -> no | T35: S | X35: ='Diccionario Datos - PostgreSQL'!X38 -> Relacion con sensores
A36: 3 | B36: ='Diccionario Datos - PostgreSQL'!B39 -> valor | C36: ='Diccionario Datos - PostgreSQL'!C39 -> valor medido | G36: DECIMAL | K36: ='Diccionario Datos - PostgreSQL'!K39 -> 10.2 | O36: ='Diccionario Datos - PostgreSQL'!O39 -> no | X36: ='Diccionario Datos - PostgreSQL'!X39
A37: 4 | B37: ='Diccionario Datos - PostgreSQL'!B40 -> fecha | C37: ='Diccionario Datos - PostgreSQL'!C40 -> fecha del registro | G37: DATETIME2 | K37: ='Diccionario Datos - PostgreSQL'!K40 | O37: ='Diccionario Datos - PostgreSQL'!O40 -> no | X37: ='Diccionario Datos - PostgreSQL'!X40
A39: ='Diccionario Datos - PostgreSQL'!A42 -> 7 | B39: Tabla | C39: ='Diccionario Datos - PostgreSQL'!C40 -> fecha del registro | G39: Descripción Tabla | K39: ='Diccionario Datos - PostgreSQL'!K42 -> Productos apícolas | X39: Versión | Y39: 2025
A40: # | B40: Campo | C40: Descripción Campo | G40: Tipo Dato - MS SQL Server | K40: Tamaño | O40: Nulo | R40: PK | T40: FK | V40: UK | X40: Nota/Comentarios
A41: 1 | B41: ='Diccionario Datos - PostgreSQL'!B44 -> id_producto | C41: ='Diccionario Datos - PostgreSQL'!C44 -> Identificador del producto | G41: IDENTITY | K41: ='Diccionario Datos - PostgreSQL'!K44 | O41: ='Diccionario Datos - PostgreSQL'!O44 -> no | R41: s | V41: S | X41: ='Diccionario Datos - PostgreSQL'!X44 -> clave primaria
A42: 2 | B42: ='Diccionario Datos - PostgreSQL'!B45 -> nombre | C42: ='Diccionario Datos - PostgreSQL'!C45 -> nombre del producto | G42: VARCHAR | K42: ='Diccionario Datos - PostgreSQL'!K45 -> 100 | O42: ='Diccionario Datos - PostgreSQL'!O45 -> no | X42: ='Diccionario Datos - PostgreSQL'!X45
A43: 3 | B43: ='Diccionario Datos - PostgreSQL'!B46 -> precio | C43: ='Diccionario Datos - PostgreSQL'!C46 -> precio | G43: DECIMAL | K43: ='Diccionario Datos - PostgreSQL'!K46 -> 10.2 | O43: ='Diccionario Datos - PostgreSQL'!O46 -> no | X43: ='Diccionario Datos - PostgreSQL'!X46
A45: ='Diccionario Datos - PostgreSQL'!A48 -> 8 | B45: Tabla | C45: ='Diccionario Datos - PostgreSQL'!C48 -> pedido | G45: Descripción Tabla | K45: ='Diccionario Datos - PostgreSQL'!K48 -> Ordenes de compra | X45: Versión | Y45: 2025
A46: # | B46: Campo | C46: Descripción Campo | G46: Tipo Dato - MS SQL Server | K46: Tamaño | O46: Nulo | R46: PK | T46: FK | V46: UK | X46: Nota/Comentarios
A47: 1 | B47: ='Diccionario Datos - PostgreSQL'!B50 -> id_pedido | C47: ='Diccionario Datos - PostgreSQL'!C50 -> identificador del pedido | G47: IDENTITY | K47: ='Diccionario Datos - PostgreSQL'!K50 | O47: ='Diccionario Datos - PostgreSQL'!O50 -> no | R47: s | V47: S | X47: ='Diccionario Datos - PostgreSQL'!X50 -> clave primaria
A48: 2 | B48: ='Diccionario Datos - PostgreSQL'!B51 -> fecha | C48: ='Diccionario Datos - PostgreSQL'!C51 -> fecha del pedido | G48: DATE | K48: ='Diccionario Datos - PostgreSQL'!K51 | O48: ='Diccionario Datos - PostgreSQL'!O51 -> no | X48: ='Diccionario Datos - PostgreSQL'!X51
...
